<?xml version="1.0"?>
<robot name="onshape">
<link name="ffld_0850ncn30_lksr00_0__6">
<visual>
<origin xyz="0.05310131103426093957 0.022056786478001109281 1.3723748428905863106e-13" rpy="1.570796322806773393 2.3540652919396952814e-14 -2.7484979288976245648" />
<geometry>
<mesh filename="package://hc10_with_hand/meshes/end_effector/ffld_0850ncn30_lksr00_0__6.stl"/>
</geometry>
<material name="ffld_0850ncn30_lksr00_0__6_material">
<color rgba="0.68627450980392157298 0.68627450980392157298 0.68627450980392157298 1.0"/>
</material>
</visual>
<!-- Shapes for ffld_0850ncn30_lksr00_0__6 -->
<collision>
<origin xyz="-0.01479645393088345473 0.034768139905676696821 0.022500000150687534534" rpy="1.570796322806773393 2.3540652919396952814e-14 -2.7484979288976245648" />
<geometry>
<box size="0.11429999999999999882 0.044999999999999998335 0.0030000000000000000625" />
</geometry>
</collision>
<collision>
<origin xyz="0.015335209541718616832 -0.034470959515271140661 0.022499999849584263745" rpy="1.5707963307830199451 -2.3540652919396952814e-14 0.39309472469216849566" />
<geometry>
<box size="0.11307699999999999696 0.044999999999999998335 0.0030000000000000000625" />
</geometry>
</collision>
<collision>
<origin xyz="0.012009762172649575407 -0.028961718088153596412 0.043499999874960081081" rpy="3.9881232233081839032e-09 -2.3540652919396952814e-14 0.39309472469216849566" />
<geometry>
<box size="0.1111540000000000028 0.015725699999999998707 0.0030000000000000000625" />
</geometry>
</collision>
<collision>
<origin xyz="0.00013806078736829097142 -0.00033293780953855614535 0.043499999998562584314" rpy="3.9881232233081839032e-09 -2.3540652919396952814e-14 0.39309472469216849566" />
<geometry>
<box size="0.1111540000000000028 0.01206100000000000054 0.0030000000000000000625" />
</geometry>
</collision>
<collision>
<origin xyz="-0.011812127323438045834 0.028485114347379509453 0.043500000122982260264" rpy="3.9881232233081839032e-09 -2.3540652919396952814e-14 0.39309472469216849566" />
<geometry>
<box size="0.1111540000000000028 0.016893899999999999889 0.0030000000000000000625" />
</geometry>
</collision>
<collision>
<origin xyz="0.063188034398928213942 -0.0061834422017654697146 0.017249999880692919868" rpy="-0.39309472469216838464 1.570796322806773393 0" />
<geometry>
<box size="0.034500000000000002887 0.018600000000000001948 0.0030000000000000000625" />
</geometry>
</collision>
<collision>
<origin xyz="0.051715718979865842042 0.021482213019861560316 0.017600000000137214218" rpy="-0.39309472469216838464 1.570796322806773393 0" />
<geometry>
<box size="0.033799999999999996714 0.041299999999999996436 0.0030000000000000000625" />
</geometry>
</collision>
<collision>
<origin xyz="0.040243403560268800612 0.049147868242777975611 0.017600000119581498542" rpy="-2.7484979288976250089 -1.570796322806773393 0" />
<geometry>
<box size="0.033799999999999996714 0.018600000000000001948 0.0030000000000000000625" />
</geometry>
</collision>
<collision>
<origin xyz="0.040243403591967007171 0.049147868166336011742 0.038350000119581506564" rpy="-2.7484979288976250089 -1.570796322806773393 0" />
<geometry>
<box size="0.007700000000000000247 0.018600000000000001948 0.0030000000000000000625" />
</geometry>
</collision>
<collision>
<origin xyz="0.063188034431161096971 -0.0061834422794968223192 0.038349999880692930976" rpy="-2.7484979288976250089 -1.570796322806773393 0" />
<geometry>
<box size="0.007700000000000000247 0.018600000000000001948 0.0030000000000000000625" />
</geometry>
</collision>
<collision>
<origin xyz="-0.063214138508734141197 0.006246388209560325977 0.017600000119578861763" rpy="0.39309472469216838464 -1.570796322806773393 0" />
<geometry>
<box size="0.033799999999999996714 0.018600000000000001948 0.0030000000000000000625" />
</geometry>
</collision>
<collision>
<origin xyz="-0.051741823089137092828 -0.021419267013356089319 0.017600000000134577438" rpy="2.7484979288976250089 1.570796322806773393 0" />
<geometry>
<box size="0.033799999999999996714 0.041299999999999996436 0.0030000000000000000625" />
</geometry>
</collision>
<collision>
<origin xyz="-0.040269507669540044459 -0.049084922236272504614 0.017599999880690279236" rpy="0.39309472469216838464 -1.570796322806773393 0" />
<geometry>
<box size="0.033799999999999996714 0.018600000000000001948 0.0030000000000000000625" />
</geometry>
</collision>
<collision>
<origin xyz="-0.04026950763784183096 -0.049084922312714482362 0.038349999880690294196" rpy="0.39309472469216838464 -1.570796322806773393 0" />
<geometry>
<box size="0.007700000000000000247 0.018600000000000001948 0.0030000000000000000625" />
</geometry>
</collision>
<collision>
<origin xyz="-0.063214138477035927699 0.0062463881331183551682 0.038350000119578869784" rpy="0.39309472469216838464 -1.570796322806773393 0" />
<geometry>
<box size="0.007700000000000000247 0.018600000000000001948 0.0030000000000000000625" />
</geometry>
</collision>
<collision>
<origin xyz="-1.3052079230378710317e-05 3.1473062564336268254e-05 0.0015000000001358846074" rpy="-3.141592649601669951 -2.3540652919396952814e-14 0.39309472469216849566" />
<geometry>
<box size="0.11359999999999999265 0.078500000000000000333 0.0030000000000000000625" />
</geometry>
</collision>
<inertial>
<origin xyz="-0.00016432911095404925737 -0.00012237677728041407299 0.021276061575975224738" rpy="0 0 0"/>
<mass value="2.9742435406123801656" />
<inertia ixx="0.0023161921097216747918" ixy="-0.00057305906837393401354"  ixz="-3.7621960169175062006e-06" iyy="0.0035329830638358363133" iyz="-1.9186990194822017588e-06" izz="0.0049122002234752871336" />
</inertial>
</link>

<link name="center_finger">
<inertial>
<origin xyz="0 0 0" rpy="0 0 0" />
<mass value="1e-9" />
<inertia ixx="0" ixy="0" ixz="0" iyy="0" iyz="0" izz="0" />
</inertial>
</link>
<joint name="center_finger_frame" type="fixed">
<origin xyz="-1.3051873192603800322e-05 3.1472560834036302163e-05 0.13750000000013595791" rpy="-2.2196766399007153304e-14 -3.9881250635755765785e-09 1.963891051487064443" />
<parent link="ffld_0850ncn30_lksr00_0__6" />
<child link="center_finger" />
<axis xyz="0 0 0"/>
</joint>

<link name="end_effector_center">
<inertial>
<origin xyz="0 0 0" rpy="0 0 0" />
<mass value="1e-9" />
<inertia ixx="0" ixy="0" ixz="0" iyy="0" iyz="0" izz="0" />
</inertial>
</link>
<joint name="end_effector_center_frame" type="fixed">
<origin xyz="0 0 -4.336808689942017736e-19" rpy="-2.3540652916961041847e-14 -3.9881232233081822489e-09 1.9638910514870651092" />
<parent link="ffld_0850ncn30_lksr00_0__6" />
<child link="end_effector_center" />
<axis xyz="0 0 0"/>
</joint>

<link name="ffld_0850ncn30_lksr00_0__3">
<visual>
<origin xyz="-0.013499999999999998113 -0.01269999999999999428 0.0097999999999999511113" rpy="1.570796326794896558 1.5707963267948961139 0" />
<geometry>
<mesh filename="package://hc10_with_hand/meshes/end_effector/ffld_0850ncn30_lksr00_0__3.stl"/>
</geometry>
<material name="ffld_0850ncn30_lksr00_0__3_material">
<color rgba="0.68627450980392157298 0.68627450980392157298 0.68627450980392157298 1.0"/>
</material>
</visual>
<!-- Shapes for ffld_0850ncn30_lksr00_0__3 -->
<collision>
<origin xyz="0.0085000000000000040801 -0.013194304999999999922 -0.0027000000000000478478" rpy="1.0131600150431524611e-25 1.5707963267948961139 0" />
<geometry>
<box size="0.024399999999999998079 0.0064113900000000003179 0.0030000000000000000625" />
</geometry>
</collision>
<collision>
<origin xyz="0.047070199999999999541 1.7347234759768070944e-18 0.0014999999999999492906" rpy="3.141592653589793116 6.2825211197003083084e-26 3.141592653589793116" />
<geometry>
<box size="0.085859599999999994258 0.01799999999999999864 0.0030000000000000000625" />
</geometry>
</collision>
<collision>
<origin xyz="0.0050000000000000009714 -0.01490000000000000005 -0.0027000000000000478478" rpy="1.570796326794896558 1.5707963267948961139 0" />
<geometry>
<box size="0.024399999999999998079 0.010000000000000000208 0.0030000000000000000625" />
</geometry>
</collision>
<collision>
<origin xyz="0.044999999999999998335 -0.00030134999999999537157 0.0079999999999999481248" rpy="2.7261089038154884094e-16 6.2825211197003083084e-26 3.141592653589793116" />
<geometry>
<box size="0.089999999999999996669 0.018602699999999999791 0.0030000000000000000625" />
</geometry>
</collision>
<collision>
<origin xyz="0.010815200000000000508 -0.01269999999999999428 0.0079999999999999515943" rpy="2.7261089038154884094e-16 6.2825211197003083084e-26 3.141592653589793116" />
<geometry>
<box size="0.012369599999999999693 0.0074000000000000003275 0.0030000000000000000625" />
</geometry>
</collision>
<collision>
<origin xyz="0.088499999999999995337 1.7347234759768070944e-18 0.0047499999999999478403" rpy="1.0131600150431524611e-25 1.5707963267948961139 0" />
<geometry>
<box size="0.0094999999999999997641 0.01799999999999999864 0.0030000000000000000625" />
</geometry>
</collision>
<collision>
<origin xyz="0.046081149999999994338 0.0075000000000000049266 0.0047499999999999461056" rpy="-1.570796326794896558 1.5707963267948961139 0" />
<geometry>
<box size="0.0094999999999999997641 0.087837700000000004663 0.0030000000000000000625" />
</geometry>
</collision>
<collision>
<origin xyz="0.050000000000000002776 -0.0074999999999999971204 0.0047499999999999478403" rpy="1.570796326794896558 -1.5707963267948961139 0" />
<geometry>
<box size="0.0094999999999999997641 0.080000000000000001665 0.0030000000000000000625" />
</geometry>
</collision>
<inertial>
<origin xyz="0.026010155325234741996 -0.0047355803699542942803 -0.0032141138333249730415" rpy="0 0 0"/>
<mass value="0.19285564776873392878" />
<inertia ixx="5.5202859436152247683e-05" ixy="-2.9112780924458255845e-05"  ixz="-5.23746968336353535e-05" iyy="0.00024511850474100832769" iyz="-1.2232725957805729746e-05" izz="0.00021268038410786007817" />
</inertial>
</link>

<joint name="fing1" type="prismatic">
<origin xyz="-1.3052014498035093004e-05 3.1472901599534017225e-05 0.045000000000135917388" rpy="0.39309472469217571211 -1.570796322806773393 0" />
<parent link="ffld_0850ncn30_lksr00_0__6" />
<child link="ffld_0850ncn30_lksr00_0__3" />
<axis xyz="0 0 1"/>
<limit effort="1" velocity="20" lower="0" upper="0.050000000000000002776"/>
<joint_properties friction="0.0"/>
</joint>

<link name="ffld_0850ncn30_lksr00_0__3_2">
<visual>
<origin xyz="-0.013499999999999998113 -0.012699999999999996014 0.0097999999999999459072" rpy="1.570796326794896558 1.570796326794896336 0" />
<geometry>
<mesh filename="package://hc10_with_hand/meshes/end_effector/ffld_0850ncn30_lksr00_0__3.stl"/>
</geometry>
<material name="ffld_0850ncn30_lksr00_0__3_material">
<color rgba="0.68627450980392157298 0.68627450980392157298 0.68627450980392157298 1.0"/>
</material>
</visual>
<!-- Shapes for ffld_0850ncn30_lksr00_0__3 -->
<collision>
<origin xyz="0.0085000000000000040801 -0.013194304999999999922 -0.002700000000000053052" rpy="-3.6029606679779289379e-25 1.570796326794896336 0" />
<geometry>
<box size="0.024399999999999998079 0.0064113900000000003179 0.0030000000000000000625" />
</geometry>
</collision>
<collision>
<origin xyz="0.047070199999999999541 0 0.0014999999999999440864" rpy="3.141592653589793116 -1.8889663167390913785e-25 -3.141592653589793116" />
<geometry>
<box size="0.085859599999999994258 0.01799999999999999864 0.0030000000000000000625" />
</geometry>
</collision>
<collision>
<origin xyz="0.0050000000000000009714 -0.01490000000000000005 -0.002700000000000053052" rpy="1.570796326794896558 1.570796326794896336 0" />
<geometry>
<box size="0.024399999999999998079 0.010000000000000000208 0.0030000000000000000625" />
</geometry>
</collision>
<collision>
<origin xyz="0.044999999999999998335 -0.00030134999999999710629 0.0079999999999999429207" rpy="2.7197515116503940362e-16 -1.8889663167390913785e-25 -3.141592653589793116" />
<geometry>
<box size="0.089999999999999996669 0.018602699999999999791 0.0030000000000000000625" />
</geometry>
</collision>
<collision>
<origin xyz="0.010815200000000000508 -0.012699999999999996014 0.0079999999999999463901" rpy="2.7197515116503940362e-16 -1.8889663167390913785e-25 -3.141592653589793116" />
<geometry>
<box size="0.012369599999999999693 0.0074000000000000003275 0.0030000000000000000625" />
</geometry>
</collision>
<collision>
<origin xyz="0.088499999999999995337 0 0.0047499999999999426362" rpy="-3.6029606679779289379e-25 1.570796326794896336 0" />
<geometry>
<box size="0.0094999999999999997641 0.01799999999999999864 0.0030000000000000000625" />
</geometry>
</collision>
<collision>
<origin xyz="0.046081149999999994338 0.0075000000000000031919 0.0047499999999999409014" rpy="-1.570796326794896558 1.570796326794896336 0" />
<geometry>
<box size="0.0094999999999999997641 0.087837700000000004663 0.0030000000000000000625" />
</geometry>
</collision>
<collision>
<origin xyz="0.050000000000000002776 -0.0074999999999999988551 0.0047499999999999426362" rpy="1.570796326794896558 -1.570796326794896336 0" />
<geometry>
<box size="0.0094999999999999997641 0.080000000000000001665 0.0030000000000000000625" />
</geometry>
</collision>
<inertial>
<origin xyz="0.026010155325234741996 -0.004735580369954296015 -0.003214113833324977812" rpy="0 0 0"/>
<mass value="0.19285564776873392878" />
<inertia ixx="5.5202859436152247683e-05" ixy="-2.9112780924458259233e-05"  ixz="-5.2374696833635346724e-05" iyy="0.0002451185047410083819" iyz="-1.2232725957805743299e-05" izz="0.00021268038410786007817" />
</inertial>
</link>

<joint name="fing2" type="prismatic">
<origin xyz="-1.3052014498050705515e-05 3.1472901599507996373e-05 0.045000000000135931266" rpy="-2.7484979288976245648 -1.570796322806773615 0" />
<parent link="ffld_0850ncn30_lksr00_0__6" />
<child link="ffld_0850ncn30_lksr00_0__3_2" />
<axis xyz="0 0 1"/>
<limit effort="1" velocity="20" lower="0" upper="0.050000000000000002776"/>
<joint_properties friction="0.0"/>
</joint>


</robot>
