<?xml version="1.0" ?>
<!-- =================================================================================== -->
<!-- |    This document was autogenerated by xacro from /home/leo/project/final_project/src/hc10_with_hand/urdf/hc10dt_full.urdf.xacro | -->
<!-- |    EDITING THIS FILE BY HAND IS NOT RECOMMENDED                                 | -->
<!-- =================================================================================== -->
<robot name="hc10_with_hand">
    <!-- link list -->
    <link name="base_link">
        <visual>
            <geometry>
                <mesh filename="package://motoman_hc10_support/meshes/hc10/visual/base_link.dae" />
            </geometry>
            <material name="">
                <color rgba="0.12941176470588237 0.14901960784313725 0.7490196078431373 1.0" />
            </material>
        </visual>
        <collision>
            <geometry>
                <mesh filename="package://motoman_hc10_support/meshes/hc10/collision/base_link.stl" />
            </geometry>
        </collision>
        <inertial>
            <mass value="0.1" />
            <origin xyz="0 0 0" rpy="0 0 0" />
            <inertia ixx="0.03" iyy="0.03" izz="0.03" ixy="0.0" ixz="0.0" iyz="0.0" />
        </inertial>
    </link>
    <link name="link_1_s">
        <visual>
            <geometry>
                <mesh filename="package://motoman_hc10_support/meshes/hc10/visual/link_1_s.dae" />
            </geometry>
            <material name="">
                <color rgba="0.12941176470588237 0.14901960784313725 0.7490196078431373 1.0" />
            </material>
        </visual>
        <collision>
            <geometry>
                <mesh filename="package://motoman_hc10_support/meshes/hc10/collision/link_1_s.stl" />
            </geometry>
        </collision>
        <inertial>
            <mass value="0.1" />
            <origin xyz="0 0 0" rpy="0 0 0" />
            <inertia ixx="0.03" iyy="0.03" izz="0.03" ixy="0.0" ixz="0.0" iyz="0.0" />
        </inertial>
    </link>
    <link name="link_2_l">
        <visual>
            <geometry>
                <mesh filename="package://motoman_hc10_support/meshes/hc10/visual/link_2_l.dae" />
            </geometry>
            <material name="">
                <color rgba="0.12941176470588237 0.14901960784313725 0.7490196078431373 1.0" />
            </material>
        </visual>
        <collision>
            <geometry>
                <mesh filename="package://motoman_hc10_support/meshes/hc10/collision/link_2_l.stl" />
            </geometry>
        </collision>
        <inertial>
            <mass value="0.1" />
            <origin xyz="0 0 0" rpy="0 0 0" />
            <inertia ixx="0.03" iyy="0.03" izz="0.03" ixy="0.0" ixz="0.0" iyz="0.0" />
        </inertial>
    </link>
    <link name="link_3_u">
        <visual>
            <geometry>
                <mesh filename="package://motoman_hc10_support/meshes/hc10/visual/link_3_u.dae" />
            </geometry>
            <material name="">
                <color rgba="0.12941176470588237 0.14901960784313725 0.7490196078431373 1.0" />
            </material>
        </visual>
        <collision>
            <geometry>
                <mesh filename="package://motoman_hc10_support/meshes/hc10/collision/link_3_u.stl" />
            </geometry>
        </collision>
        <inertial>
            <mass value="0.1" />
            <origin xyz="0 0 0" rpy="0 0 0" />
            <inertia ixx="0.03" iyy="0.03" izz="0.03" ixy="0.0" ixz="0.0" iyz="0.0" />
        </inertial>
    </link>
    <link name="link_4_r">
        <visual>
            <geometry>
                <mesh filename="package://motoman_hc10_support/meshes/hc10/visual/link_4_r.dae" />
            </geometry>
            <material name="">
                <color rgba="0.12941176470588237 0.14901960784313725 0.7490196078431373 1.0" />
            </material>
        </visual>
        <collision>
            <geometry>
                <mesh filename="package://motoman_hc10_support/meshes/hc10/collision/link_4_r.stl" />
            </geometry>
        </collision>
        <inertial>
            <mass value="0.1" />
            <origin xyz="0 0 0" rpy="0 0 0" />
            <inertia ixx="0.03" iyy="0.03" izz="0.03" ixy="0.0" ixz="0.0" iyz="0.0" />
        </inertial>
    </link>
    <link name="link_5_b">
        <visual>
            <geometry>
                <mesh filename="package://motoman_hc10_support/meshes/hc10/visual/link_5_b.dae" />
            </geometry>
            <material name="">
                <color rgba="0.12941176470588237 0.14901960784313725 0.7490196078431373 1.0" />
            </material>
        </visual>
        <collision>
            <geometry>
                <mesh filename="package://motoman_hc10_support/meshes/hc10/collision/link_5_b.stl" />
            </geometry>
        </collision>
        <inertial>
            <mass value="0.1" />
            <origin xyz="0 0 0" rpy="0 0 0" />
            <inertia ixx="0.03" iyy="0.03" izz="0.03" ixy="0.0" ixz="0.0" iyz="0.0" />
        </inertial>
    </link>
    <link name="link_6_t">
        <visual>
            <geometry>
                <mesh filename="package://motoman_hc10_support/meshes/hc10dt/visual/link_6_t.dae" />
            </geometry>
            <material name="">
                <color rgba="0.12941176470588237 0.14901960784313725 0.7490196078431373 1.0" />
            </material>
        </visual>
        <collision>
            <geometry>
                <mesh filename="package://motoman_hc10_support/meshes/hc10dt/collision/link_6_t.stl" />
            </geometry>
        </collision>
        <inertial>
            <mass value="0.1" />
            <origin xyz="0 0 0" rpy="0 0 0" />
            <inertia ixx="0.03" iyy="0.03" izz="0.03" ixy="0.0" ixz="0.0" iyz="0.0" />
        </inertial>
    </link>
    <link name="tool0" />
    <!-- end of link list -->
    <!-- joint list -->
    <joint name="joint_1_s" type="revolute">
        <parent link="base_link" />
        <child link="link_1_s" />
        <origin rpy="0 0 0" xyz="0 0 0.275" />
        <axis xyz="0 0 1" />
        <limit effort="368.48" lower="-3.141592653589793" upper="3.141592653589793" velocity="2.2689280275926285" />
    </joint>
    <joint name="joint_2_l" type="revolute">
        <parent link="link_1_s" />
        <child link="link_2_l" />
        <origin rpy="0 0 0" xyz="0 0 0" />
        <axis xyz="0 1 0" />
        <limit effort="368.48" lower="-3.141592653589793" upper="3.141592653589793" velocity="2.2689280275926285" />
    </joint>
    <joint name="joint_3_u" type="revolute">
        <parent link="link_2_l" />
        <child link="link_3_u" />
        <origin rpy="0 0 0" xyz="0 0 0.700" />
        <axis xyz="0 -1 0" />
        <limit effort="141.12" lower="-0.08726646259971647" upper="6.19591884457987" velocity="3.141592653589793" />
    </joint>
    <joint name="joint_4_r" type="revolute">
        <parent link="link_3_u" />
        <child link="link_4_r" />
        <origin rpy="0 0 0" xyz="0 0 -0.500" />
        <axis xyz="0 0 1" />
        <limit effort="39.20" lower="-3.141592653589793" upper="3.141592653589793" velocity="3.141592653589793" />
    </joint>
    <joint name="joint_5_b" type="revolute">
        <parent link="link_4_r" />
        <child link="link_5_b" />
        <origin rpy="0 0 0" xyz="0 0.162 0" />
        <axis xyz="0 -1 0" />
        <limit effort="31.36" lower="-3.141592653589793" upper="3.141592653589793" velocity="4.363323129985824" />
    </joint>
    <joint name="joint_6_t" type="revolute">
        <parent link="link_5_b" />
        <child link="link_6_t" />
        <origin rpy="0 0 0" xyz="0 0 0" />
        <axis xyz="0 0 1" />
        <limit effort="31.36" lower="-3.141592653589793" upper="3.141592653589793" velocity="4.363323129985824" />
    </joint>
    <joint name="joint_6_t-tool0" type="fixed">
        <origin rpy="3.141592653589793 0 0" xyz="0 0 -0.170" />
        <parent link="link_6_t" />
        <child link="tool0" />
    </joint>
    <!-- end of joint list -->
    <!-- ROS base_link to Robot Manufacturer World Coordinates transform -->
    <link name="base" />
    <joint name="base_link-base" type="fixed">
        <origin rpy="0 0 0" xyz="0 0 0.275" />
        <parent link="base_link" />
        <child link="base" />
    </joint>
    <link name="part_1">
        <visual>
            <origin rpy="0 -0 0" xyz="-0.35000000000000003331 0 0" />
            <geometry>
                <mesh filename="package://hc10_with_hand/meshes/agv2/part_1.stl" />
            </geometry>
            <material name="part_1_material">
                <color rgba="0.043137254901960783715 0.21568627450980393245 0.40392156862745098866 1.0" />
            </material>
        </visual>
        <collision>
            <origin rpy="0 -0 0" xyz="-0.35000000000000003331 0 0" />
            <geometry>
                <mesh filename="package://hc10_with_hand/meshes/agv2/part_1.stl" />
            </geometry>
        </collision>
        <inertial>
            <origin rpy="0 0 0" xyz="-5.5511151231257827021e-17 0.63400000000000000799 0.37981666666666674681" />
            <mass value="4945.500000000001819" />
            <inertia ixx="837.31419627625041358" ixy="1.0274208650518092216e-13" ixz="1.4222477333000753134e-14" iyy="451.51244427625027811" iyz="-62.245216950000028078" izz="789.68425200000012865" />
        </inertial>
    </link>
    <link name="arm_position">
        <inertial>
            <origin rpy="0 0 0" xyz="0 0 0" />
            <mass value="1e-9" />
            <inertia ixx="0" ixy="0" ixz="0" iyy="0" iyz="0" izz="0" />
        </inertial>
    </link>
    <joint name="arm_position_frame" type="fixed">
        <origin rpy="0 -0 -1.570796326794896558" xyz="-1.6656406986375213093e-16 0.29999999999999982236 0.66500000000000036859" />
        <parent link="part_1" />
        <child link="arm_position" />
        <axis xyz="0 0 0" />
    </joint>
    <link name="ffld_0850ncn30_lksr00_0__6">
        <visual>
            <origin rpy="1.5707963197624172924 -9.3043403012065366432e-09 -3.1383258088491423621" xyz="0.057499581136592189945 0.0002219151046475575928 0.012999999465240053009" />
            <geometry>
                <mesh filename="package://hc10_with_hand/meshes/end_effector/ffld_0850ncn30_lksr00_0__6.stl" />
            </geometry>
            <material name="ffld_0850ncn30_lksr00_0__6_material">
                <color rgba="0.68627450980392157298 0.68627450980392157298 0.68627450980392157298 1.0" />
            </material>
        </visual>
        <collision>
            <origin rpy="1.5707963197624172924 -9.3043403012065366432e-09 -3.1383258088491423621" xyz="0.057499581136592189945 0.0002219151046475575928 0.012999999465240053009" />
            <geometry>
                <mesh filename="package://hc10_with_hand/meshes/end_effector/ffld_0850ncn30_lksr00_0__6.stl" />
            </geometry>
        </collision>
        <visual>
            <origin rpy="1.5707963197624170704 -9.3043400791619201376e-09 -3.138325808849141918" xyz="0.05749958580022360155 0.00022191160362493300706 0.51299999946524066363" />
            <geometry>
                <mesh filename="package://hc10_with_hand/meshes/end_effector/support_end_effector.stl" />
            </geometry>
            <material name="support_end_effector_material">
                <color rgba="0.61568627450980395466 0.81176470588235294379 0.92941176470588238168 1.0" />
            </material>
        </visual>
        <collision>
            <origin rpy="1.5707963197624170704 -9.3043400791619201376e-09 -3.138325808849141918" xyz="0.05749958580022360155 0.00022191160362493300706 0.51299999946524066363" />
            <geometry>
                <mesh filename="package://hc10_with_hand/meshes/end_effector/support_end_effector.stl" />
            </geometry>
        </collision>
        <inertial>
            <origin rpy="0 0 0" xyz="-0.00017124515018543807858 -0.00032649461781921829216 0.030490247070913023553" />
            <mass value="3.4292542988302696649" />
            <inertia ixx="0.0026649603191174243977" ixy="1.9310786724948536671e-05" ixz="-1.8842537492230146118e-06" iyy="0.0046547440941269481451" iyz="-2.721762450203936949e-05" izz="0.0057258445196087144613" />
        </inertial>
    </link>
    <link name="center_finger">
        <inertial>
            <origin rpy="0 0 0" xyz="0 0 0" />
            <mass value="1e-9" />
            <inertia ixx="0" ixy="0" ixz="0" iyy="0" iyz="0" izz="0" />
        </inertial>
    </link>
    <joint name="center_finger_frame" type="fixed">
        <origin rpy="9.3043404330455770657e-09 -7.0324804683672409296e-09 1.5740631715355417608" xyz="-1.1077846809835756314e-07 3.407092089739716112e-05 0.14800000000024016167" />
        <parent link="ffld_0850ncn30_lksr00_0__6" />
        <child link="center_finger" />
        <axis xyz="0 0 0" />
    </joint>
    <link name="end_effector_center">
        <inertial>
            <origin rpy="0 0 0" xyz="0 0 0" />
            <mass value="1e-9" />
            <inertia ixx="0" ixy="0" ixz="0" iyy="0" iyz="0" izz="0" />
        </inertial>
    </link>
    <joint name="end_effector_center_frame" type="fixed">
        <origin rpy="9.3043401069174907901e-09 -7.0324793788390369411e-09 1.5740631715355455356" xyz="1.2125441276045201278e-10 -9.1026602921928656542e-11 0.012999999999999997669" />
        <parent link="ffld_0850ncn30_lksr00_0__6" />
        <child link="end_effector_center" />
        <axis xyz="0 0 0" />
    </joint>
    <link name="arm_to_hand">
        <inertial>
            <origin rpy="0 0 0" xyz="0 0 0" />
            <mass value="1e-9" />
            <inertia ixx="0" ixy="0" ixz="0" iyy="0" iyz="0" izz="0" />
        </inertial>
    </link>
    <joint name="arm_to_hand_frame" type="fixed">
        <origin rpy="7.0324800430257777421e-09 9.3043403012065234083e-09 0.003266844740651022802" xyz="0 0 0" />
        <parent link="arm_to_hand" />
        <child link="ffld_0850ncn30_lksr00_0__6" />
        <axis xyz="0 0 0" />
    </joint>
    <link name="hand_to_camera">
        <inertial>
            <origin rpy="0 0 0" xyz="0 0 0" />
            <mass value="1e-9" />
            <inertia ixx="0" ixy="0" ixz="0" iyy="0" iyz="0" izz="0" />
        </inertial>
    </link>
    <joint name="hand_to_camera_frame" type="fixed">
        <origin rpy="7.0324804106860020408e-09 9.3043403012065366432e-09 0.0032668447406510223684" xyz="-0.0073555144854190873671 -0.044240193231909627491 0.002999999758834949893" />
        <parent link="ffld_0850ncn30_lksr00_0__6" />
        <child link="hand_to_camera" />
        <axis xyz="0 0 0" />
    </joint>
    <link name="ffld_0850ncn30_lksr00_0__3">
        <visual>
            <origin rpy="1.570796326794896558 1.570796326794896336 0" xyz="-0.013499999999999998113 -0.012699999999999996014 0.0097999999999999459072" />
            <geometry>
                <mesh filename="package://hc10_with_hand/meshes/end_effector/ffld_0850ncn30_lksr00_0__3.stl" />
            </geometry>
            <material name="ffld_0850ncn30_lksr00_0__3_material">
                <color rgba="0.68627450980392157298 0.68627450980392157298 0.68627450980392157298 1.0" />
            </material>
        </visual>
        <collision>
            <origin rpy="1.570796326794896558 1.570796326794896336 0" xyz="-0.013499999999999998113 -0.012699999999999996014 0.0097999999999999459072" />
            <geometry>
                <mesh filename="package://hc10_with_hand/meshes/end_effector/ffld_0850ncn30_lksr00_0__3.stl" />
            </geometry>
        </collision>
        <inertial>
            <origin rpy="0 0 0" xyz="0.026010155325234741996 -0.0047355803699542925456 -0.003214113833324977812" />
            <mass value="0.19285564776873392878" />
            <inertia ixx="5.5202859436152247683e-05" ixy="-2.9112780924458249069e-05" ixz="-5.23746968336353535e-05" iyy="0.00024511850474100843611" iyz="-1.2232725957805765321e-05" izz="0.00021268038410786007817" />
        </inertial>
    </link>
    
    <joint name="fing1" type="prismatic">
        <origin rpy="0.0032668447406510748438 -1.5707963151318564687 0" xyz="-1.1161792179241458722e-07 3.4071551081503448355e-05 0.058000000000239609887" />
        <parent link="ffld_0850ncn30_lksr00_0__6" />
        <child link="ffld_0850ncn30_lksr00_0__3" />
        <axis xyz="0 0 1" />
        <limit effort="80" lower="0" upper="0.050000000000000002776" velocity="20" />
        <joint_properties friction="0.01" />
    </joint>
    <link name="ffld_0850ncn30_lksr00_0__3_2">
        <visual>
            <origin rpy="1.570796326794896558 1.570796326794896336 0" xyz="-0.013499999999999998113 -0.012699999999999997749 0.0097999999999999476419" />
            <geometry>
                <mesh filename="package://hc10_with_hand/meshes/end_effector/ffld_0850ncn30_lksr00_0__3.stl" />
            </geometry>
            <material name="ffld_0850ncn30_lksr00_0__3_material">
                <color rgba="0.68627450980392157298 0.68627450980392157298 0.68627450980392157298 1.0" />
            </material>
        </visual>
        <collision>
            <origin rpy="1.570796326794896558 1.570796326794896336 0" xyz="-0.013499999999999998113 -0.012699999999999997749 0.0097999999999999476419" />
            <geometry>
                <mesh filename="package://hc10_with_hand/meshes/end_effector/ffld_0850ncn30_lksr00_0__3.stl" />
            </geometry>
        </collision>
        <inertial>
            <origin rpy="0 0 0" xyz="0.026010155325234741996 -0.0047355803699542942803 -0.0032141138333249760772" />
            <mass value="0.19285564776873392878" />
            <inertia ixx="5.5202859436152247683e-05" ixy="-2.9112780924458249069e-05" ixz="-5.23746968336353535e-05" iyy="0.00024511850474100843611" iyz="-1.2232725957805765321e-05" izz="0.00021268038410786007817" />
        </inertial>
    </link>
    <joint name="fing2" type="prismatic">
        <origin rpy="-3.1383258088491423621 -1.5707963151318573569 0" xyz="-1.1161792179588403418e-07 3.4071551081512121972e-05 0.058000000000239672338" />
        <parent link="ffld_0850ncn30_lksr00_0__6" />
        <child link="ffld_0850ncn30_lksr00_0__3_2" />
        <axis xyz="0 0 1" />
        <limit effort="80" lower="0" upper="0.050000000000000002776" velocity="20" />
        <joint_properties friction="0.01" />
    </joint>
    <link name="camera_sup2">
        <visual>
            <origin rpy="1.570796326794896558 6.6613381477509234653e-16 -1.570796326794896558" xyz="-0.044250000000000101752 0.064999999999999655276 0.51000000000000034195" />
            <geometry>
                <mesh filename="package://hc10_with_hand/meshes/camera/camera_sup2.stl" />
            </geometry>
            <material name="camera_sup2_material">
                <color rgba="0.91764705882352937127 0.91764705882352937127 0.91764705882352937127 1.0" />
            </material>
        </visual>
        <collision>
            <origin rpy="1.570796326794896558 6.6613381477509234653e-16 -1.570796326794896558" xyz="-0.044250000000000101752 0.064999999999999655276 0.51000000000000034195" />
            <geometry>
                <mesh filename="package://hc10_with_hand/meshes/camera/camera_sup2.stl" />
            </geometry>
        </collision>
        <visual>
            <origin rpy="1.570796326794896558 6.6613381477509234653e-16 -1.570796326794896558" xyz="-0.045084453531127645365 0.064999999999999655276 0.51000000000000045297" />
            <geometry>
                <mesh filename="package://hc10_with_hand/meshes/camera/camera_link.stl" />
            </geometry>
            <material name="camera_link_material">
                <color rgba="0.76862745098039220171 0.88627450980392152857 0.95294117647058818044 1.0" />
            </material>
        </visual>
        <collision>
            <origin rpy="1.570796326794896558 6.6613381477509234653e-16 -1.570796326794896558" xyz="-0.045084453531127645365 0.064999999999999655276 0.51000000000000045297" />
            <geometry>
                <mesh filename="package://hc10_with_hand/meshes/camera/camera_link.stl" />
            </geometry>
        </collision>
        <inertial>
            <origin rpy="0 0 0" xyz="0.04949093212775205336 0.0074999999999999372724 0.029126341361751767467" />
            <mass value="0.44949998079333491896" />
            <inertia ixx="0.00025885935812457525193" ixy="-9.4509154105318211273e-21" ixz="-6.3216991564398030949e-06" iyy="0.00024727718204468863376" iyz="-3.5333537328324862512e-20" izz="0.00030425868802670864464" />
        </inertial>
    </link>
    <link name="camera_to_hand">
        <inertial>
            <origin rpy="0 0 0" xyz="0 0 0" />
            <mass value="1e-9" />
            <inertia ixx="0" ixy="0" ixz="0" iyy="0" iyz="0" izz="0" />
        </inertial>
    </link>
    <joint name="camera_to_hand_frame" type="fixed">
        <origin rpy="6.6613381477509185349e-16 5.6699377562760083384e-31 1.3877787807814422859e-17" xyz="1.2986865570217543499e-17 -6.9676108198468406655e-17 -3.3306690738754696213e-16" />
        <parent link="camera_to_hand" />
        <child link="camera_sup2" />
        <axis xyz="0 0 0" />
    </joint>
    <link name="camera_link_view">
        <inertial>
            <origin rpy="0 0 0" xyz="0 0 0" />
            <mass value="1e-9" />
            <inertia ixx="0" ixy="0" ixz="0" iyy="0" iyz="0" izz="0" />
        </inertial>
    </link>
    <joint name="camera_link_view_frame" type="fixed">
        <origin rpy="-5.6699377562760144691e-31 6.6613381477509234653e-16 -1.570796326794896558" xyz="0.050000000000000134615 0.0074999999999999103842 0.049999999999999732159" />
        <parent link="camera_sup2" />
        <child link="camera_link_view" />
        <axis xyz="0 0 0" />
    </joint>
    
    <joint name="camera_optical_joint" type="fixed">
        <origin rpy="0 -1.5707963267948966 1.5707963267948966" xyz="0 0 0" />
        <parent link="camera_link_view" />
        <child link="camera_link_optical" />
    </joint>
    
    <link name="camera_link_optical" >
        </link>
    
    <joint name="camera_rviz_joint" type="fixed">
    <origin xyz="0 0 0" rpy="-1.5707963267948966 0 -1.5707963267948966"/>
    <parent link="camera_link_optical"/>
    <child link="camera_rviz"/>
  </joint>
      <link name="camera_rviz">
  </link>
    
    <gazebo reference="camera_link_optical">
        <material>Gazebo/Red</material>
        <sensor name="camera" type="camera">
            <pose>0 0 0 0 0 0</pose>
            <visualize>true</visualize>
            <update_rate>10</update_rate>
            <camera >
                <horizontal_fov>1.42419</horizontal_fov>
                <image>
                    <format>R8G8B8</format>
                    <width>1920</width>
                    <height>1080</height>
                </image>
                <clip>
                    <near>0.05</near>
                    <far>8.0</far>
                </clip>
            </camera>
            <plugin filename="libgazebo_ros_camera.so" name="camera_controller">
                <frame_name>camera_rviz</frame_name>
                <robotNamespace>/camera_rect</robotNamespace>
                
            </plugin>
        </sensor>
        <plugin name="gazebo_ros_control">
            
        </plugin>
    </gazebo>
    <joint name="$agv_arm_joint" type="fixed">
        <parent link="arm_position" />
        <child link="base_link" />
        <origin rpy="0 0 -1.5707963267948966" xyz="0 0 0" />
    </joint>
    <joint name="$hand_tool_joint" type="fixed">
        <parent link="tool0" />
        <child link="arm_to_hand" />
        <origin rpy="0 0 0" xyz="0 0 0" />
    </joint>
    <joint name="$camera_joint" type="fixed">
        <parent link="hand_to_camera" />
        <child link="camera_to_hand" />
        <origin rpy="0 0 -1.5707963267948966" xyz="0 0 0" />
    </joint>
    <transmission name="trans_joint_1_s">
        <type>transmission_interface/SimpleTransmission</type>
        <joint name="joint_1_s">
            <hardwareInterface>hardware_interface/PositionJointInterface</hardwareInterface>
        </joint>
        <actuator name="joint_1_s_motor">
            <hardwareInterface>hardware_interface/PositionJointInterface</hardwareInterface>
            <mechanicalReduction>1</mechanicalReduction>
        </actuator>
    </transmission>
    <transmission name="trans_joint_2_l">
        <type>transmission_interface/SimpleTransmission</type>
        <joint name="joint_2_l">
            <hardwareInterface>hardware_interface/PositionJointInterface</hardwareInterface>
        </joint>
        <actuator name="joint_2_l_motor">
            <hardwareInterface>hardware_interface/PositionJointInterface</hardwareInterface>
            <mechanicalReduction>1</mechanicalReduction>
        </actuator>
    </transmission>
    <transmission name="trans_joint_3_u">
        <type>transmission_interface/SimpleTransmission</type>
        <joint name="joint_3_u">
            <hardwareInterface>hardware_interface/PositionJointInterface</hardwareInterface>
        </joint>
        <actuator name="joint_3_u_motor">
            <hardwareInterface>hardware_interface/PositionJointInterface</hardwareInterface>
            <mechanicalReduction>1</mechanicalReduction>
        </actuator>
    </transmission>
    <transmission name="trans_joint_4_r">
        <type>transmission_interface/SimpleTransmission</type>
        <joint name="joint_4_r">
            <hardwareInterface>hardware_interface/PositionJointInterface</hardwareInterface>
        </joint>
        <actuator name="joint_4_r_motor">
            <hardwareInterface>hardware_interface/PositionJointInterface</hardwareInterface>
            <mechanicalReduction>1</mechanicalReduction>
        </actuator>
    </transmission>
    <transmission name="trans_joint_5_b">
        <type>transmission_interface/SimpleTransmission</type>
        <joint name="joint_5_b">
            <hardwareInterface>hardware_interface/PositionJointInterface</hardwareInterface>
        </joint>
        <actuator name="joint_5_b_motor">
            <hardwareInterface>hardware_interface/PositionJointInterface</hardwareInterface>
            <mechanicalReduction>1</mechanicalReduction>
        </actuator>
    </transmission>
    <transmission name="trans_joint_6_t">
        <type>transmission_interface/SimpleTransmission</type>
        <joint name="joint_6_t">
            <hardwareInterface>hardware_interface/PositionJointInterface</hardwareInterface>
        </joint>
        <actuator name="joint_6_t_motor">
            <hardwareInterface>hardware_interface/PositionJointInterface</hardwareInterface>
            <mechanicalReduction>1</mechanicalReduction>
        </actuator>
    </transmission>
    <transmission name="trans_fing1">
        <type>transmission_interface/SimpleTransmission</type>
        <joint name="fing1">
            <hardwareInterface>hardware_interface/PositionJointInterface</hardwareInterface>
        </joint>
        <actuator name="fing1_motor">
            <hardwareInterface>hardware_interface/PositionJointInterface</hardwareInterface>
            <mechanicalReduction>1</mechanicalReduction>
        </actuator>
    </transmission>
    <transmission name="trans_fing2">
        <type>transmission_interface/SimpleTransmission</type>
        <joint name="fing2">
            <hardwareInterface>hardware_interface/PositionJointInterface</hardwareInterface>
        </joint>
        <actuator name="fing2_motor">
            <hardwareInterface>hardware_interface/PositionJointInterface</hardwareInterface>
            <mechanicalReduction>1</mechanicalReduction>
        </actuator>
    </transmission>
    
    <gazebo>
        <plugin filename="libgazebo_ros_control.so" name="gazebo_ros_control">
            <robotNamespace>/</robotNamespace>
        </plugin>
    </gazebo>
</robot>

