<?xml version="1.0"?>
<robot name="end_effector">
<link name="ffld_0850ncn30_lksr00_0__6">
<visual>
<origin xyz="0.057499581136592189945 0.0002219151046475575928 0.012999999465240053009" rpy="1.5707963197624172924 -9.3043403012065366432e-09 -3.1383258088491423621" />
<geometry>
<mesh filename="package://hc10_with_hand/meshes/end_effector/ffld_0850ncn30_lksr00_0__6.stl"/>
</geometry>
<material name="ffld_0850ncn30_lksr00_0__6_material">
<color rgba="0.68627450980392157298 0.68627450980392157298 0.68627450980392157298 1.0"/>
</material>
</visual>
<collision>
<origin xyz="0.057499581136592189945 0.0002219151046475575928 0.012999999465240053009" rpy="1.5707963197624172924 -9.3043403012065366432e-09 -3.1383258088491423621" />
<geometry>
<mesh filename="package://hc10_with_hand/meshes/end_effector/ffld_0850ncn30_lksr00_0__6.stl"/>
</geometry>
</collision>
<visual>
<origin xyz="0.05749958580022360155 0.00022191160362493300706 0.51299999946524066363" rpy="1.5707963197624170704 -9.3043400791619201376e-09 -3.138325808849141918" />
<geometry>
<mesh filename="package://hc10_with_hand/meshes/end_effector/support_end_effector.stl"/>
</geometry>
<material name="support_end_effector_material">
<color rgba="0.61568627450980395466 0.81176470588235294379 0.92941176470588238168 1.0"/>
</material>
</visual>
<collision>
<origin xyz="0.05749958580022360155 0.00022191160362493300706 0.51299999946524066363" rpy="1.5707963197624170704 -9.3043400791619201376e-09 -3.138325808849141918" />
<geometry>
<mesh filename="package://hc10_with_hand/meshes/end_effector/support_end_effector.stl"/>
</geometry>
</collision>
<inertial>
<origin xyz="-0.00017124515018543807858 -0.00032649461781921829216 0.030490247070913023553" rpy="0 0 0"/>
<mass value="3.4292542988302696649" />
<inertia ixx="0.0026649603191174243977" ixy="1.9310786724948536671e-05"  ixz="-1.8842537492230146118e-06" iyy="0.0046547440941269481451" iyz="-2.721762450203936949e-05" izz="0.0057258445196087144613" />
</inertial>
</link>

<link name="center_finger">
<inertial>
<origin xyz="0 0 0" rpy="0 0 0" />
<mass value="1e-9" />
<inertia ixx="0" ixy="0" ixz="0" iyy="0" iyz="0" izz="0" />
</inertial>
</link>
<joint name="center_finger_frame" type="fixed">
<origin xyz="-1.1077846809835756314e-07 3.407092089739716112e-05 0.14800000000024016167" rpy="9.3043404330455770657e-09 -7.0324804683672409296e-09 1.5740631715355417608" />
<parent link="ffld_0850ncn30_lksr00_0__6" />
<child link="center_finger" />
<axis xyz="0 0 0"/>
</joint>

<link name="end_effector_center">
<inertial>
<origin xyz="0 0 0" rpy="0 0 0" />
<mass value="1e-9" />
<inertia ixx="0" ixy="0" ixz="0" iyy="0" iyz="0" izz="0" />
</inertial>
</link>
<joint name="end_effector_center_frame" type="fixed">
<origin xyz="1.2125441276045201278e-10 -9.1026602921928656542e-11 0.012999999999999997669" rpy="9.3043401069174907901e-09 -7.0324793788390369411e-09 1.5740631715355455356" />
<parent link="ffld_0850ncn30_lksr00_0__6" />
<child link="end_effector_center" />
<axis xyz="0 0 0"/>
</joint>

<link name="arm_to_hand">
<inertial>
<origin xyz="0 0 0" rpy="0 0 0" />
<mass value="1e-9" />
<inertia ixx="0" ixy="0" ixz="0" iyy="0" iyz="0" izz="0" />
</inertial>
</link>
<joint name="arm_to_hand_frame" type="fixed">
<origin xyz="0 0 0" rpy="7.0324800430257777421e-09 9.3043403012065234083e-09 0.003266844740651022802" />
<parent link="arm_to_hand" />
<child link="ffld_0850ncn30_lksr00_0__6" />
<axis xyz="0 0 0"/>
</joint>

<link name="hand_to_camera">
<inertial>
<origin xyz="0 0 0" rpy="0 0 0" />
<mass value="1e-9" />
<inertia ixx="0" ixy="0" ixz="0" iyy="0" iyz="0" izz="0" />
</inertial>
</link>
<joint name="hand_to_camera_frame" type="fixed">
<origin xyz="-0.0073555144854190873671 -0.044240193231909627491 0.002999999758834949893" rpy="7.0324804106860020408e-09 9.3043403012065366432e-09 0.0032668447406510223684" />
<parent link="ffld_0850ncn30_lksr00_0__6" />
<child link="hand_to_camera" />
<axis xyz="0 0 0"/>
</joint>

<link name="ffld_0850ncn30_lksr00_0__3">
<visual>
<origin xyz="-0.013499999999999998113 -0.012699999999999996014 0.0097999999999999459072" rpy="1.570796326794896558 1.570796326794896336 0" />
<geometry>
<mesh filename="package://hc10_with_hand/meshes/end_effector/ffld_0850ncn30_lksr00_0__3.stl"/>
</geometry>
<material name="ffld_0850ncn30_lksr00_0__3_material">
<color rgba="0.68627450980392157298 0.68627450980392157298 0.68627450980392157298 1.0"/>
</material>
</visual>
<collision>
<origin xyz="-0.013499999999999998113 -0.012699999999999996014 0.0097999999999999459072" rpy="1.570796326794896558 1.570796326794896336 0" />
<geometry>
<mesh filename="package://hc10_with_hand/meshes/end_effector/ffld_0850ncn30_lksr00_0__3.stl"/>
</geometry>
</collision>
<inertial>
<origin xyz="0.026010155325234741996 -0.0047355803699542925456 -0.003214113833324977812" rpy="0 0 0"/>
<mass value="0.19285564776873392878" />
<inertia ixx="5.5202859436152247683e-05" ixy="-2.9112780924458249069e-05"  ixz="-5.23746968336353535e-05" iyy="0.00024511850474100843611" iyz="-1.2232725957805765321e-05" izz="0.00021268038410786007817" />
</inertial>
</link>

<joint name="fing1" type="prismatic">
<origin xyz="-1.1161792179241458722e-07 3.4071551081503448355e-05 0.058000000000239609887" rpy="0.0032668447406510748438 -1.5707963151318564687 0" />
<parent link="ffld_0850ncn30_lksr00_0__6" />
<child link="ffld_0850ncn30_lksr00_0__3" />
<axis xyz="0 0 1"/>
<limit effort="1" velocity="20" lower="0" upper="0.050000000000000002776"/>
<joint_properties friction="0.0"/>
</joint>

<link name="ffld_0850ncn30_lksr00_0__3_2">
<visual>
<origin xyz="-0.013499999999999998113 -0.012699999999999997749 0.0097999999999999476419" rpy="1.570796326794896558 1.570796326794896336 0" />
<geometry>
<mesh filename="package://hc10_with_hand/meshes/end_effector/ffld_0850ncn30_lksr00_0__3.stl"/>
</geometry>
<material name="ffld_0850ncn30_lksr00_0__3_material">
<color rgba="0.68627450980392157298 0.68627450980392157298 0.68627450980392157298 1.0"/>
</material>
</visual>
<collision>
<origin xyz="-0.013499999999999998113 -0.012699999999999997749 0.0097999999999999476419" rpy="1.570796326794896558 1.570796326794896336 0" />
<geometry>
<mesh filename="package://hc10_with_hand/meshes/end_effector/ffld_0850ncn30_lksr00_0__3.stl"/>
</geometry>
</collision>
<inertial>
<origin xyz="0.026010155325234741996 -0.0047355803699542942803 -0.0032141138333249760772" rpy="0 0 0"/>
<mass value="0.19285564776873392878" />
<inertia ixx="5.5202859436152247683e-05" ixy="-2.9112780924458249069e-05"  ixz="-5.23746968336353535e-05" iyy="0.00024511850474100843611" iyz="-1.2232725957805765321e-05" izz="0.00021268038410786007817" />
</inertial>
</link>

<joint name="fing2" type="prismatic">
<origin xyz="-1.1161792179588403418e-07 3.4071551081512121972e-05 0.058000000000239672338" rpy="-3.1383258088491423621 -1.5707963151318573569 0" />
<parent link="ffld_0850ncn30_lksr00_0__6" />
<child link="ffld_0850ncn30_lksr00_0__3_2" />
<axis xyz="0 0 1"/>
<limit effort="1" velocity="20" lower="0" upper="0.050000000000000002776"/>
<joint_properties friction="0.0"/>
</joint>


</robot>
